Workbook

Sheet Lista de bosquejos
A1: DISCURSOS PÚBLICOS PRONUNCIADOS
B2: TEMA | C2: FECHA QUE SE PRESENTO
A3: Num. | B3: Titulo | C3: 2026 | D3: 2027
A4: 1 | B4: ¿Conoce bien a Dios?
A5: 2 | B5: ¿Sobreviviremos a los últimos días?
A6: 3 | B6: Avancemos con la organización unida de Jehová
A7: 4 | B7: El mundo que nos rodea prueba que Dios existe
A8: 5 | B8: Ayuda práctica para las familias
A9: 6 | B9: ¿Qué aprendemos del diluvio universal?
A10: 7 | B10: Imitemos al “Padre de tiernas misericordias"
A11: 8 | B11: Vivamos para hacer la voluntad de Dios, no la nuestra
A12: 9 | B12: Escuchemos y pongamos en práctica la Palabra de Dios
A13: 10 | B13: Seamos honrados en todo
A14: 11 | B14: Imitemos a Jesús, y no seamos parte del mundo
A15: 12 | B15: A Dios le importa cómo vemos la autoridad
... A34: 31 | B34: ¿Estamos al tanto de nuestras necesidades espirituales?
A35: 32 | B35: Cómo enfrentarse a las inquietudes de la vida | C35: 46026
A36: 33 | B36: ¿Habrá algún día justicia para todos?
A37: 34 | B37: ¿Tendrá usted la marca para sobrevivir? | C37: 46082
A38: 35 | B38: ¿Se puede vivir para siempre? ¿Lo logrará usted?
A39: 36 | B39: ¿Es esta vida todo lo que podamos esperar?
A40: 37 | B40: ¿Por qué andar en el camino de Dios?
A41: 38 | B41: ¿Cómo puede usted sobrevivir al fin del mundo?
A42: 39 | B42: ¿En qué sentido es Jesucristo el vencedor del mundo?
A43: 40 | B43: ¿Qué sucederá en el futuro cercano?
A44: 41 | B44: "Estense quietos y vean cómo los salva Jehová"
A45: 42 | B45: ¿Puede el amor vencer al odio?
A46: 43 | B46: Lo que Dios espera de nosotros siempre nos beneficia
A47: 44 | B47: ¿Cómo le benefician a usted las enseñanzas de Jesús?
A48: 45 | B48: Sigamos el camino que lleva a la vida
A49: 46 | B49: Mantengamos nuestra confianza fuerte hasta el fin
... A68: 65 | B68: ¿Cómo podemos ser pacíficos en un mundo violento?
A69: 66 | B69: ¿Será usted un buen trabajador en la cosecha? | C69: 46047
A70: 67 | B70: Medite en la Palabra de Jehová y en su creación
A71: 68 | B71: “Sigan [...] perdonándose con generosidad”
A72: 69 | B72: ¿Por qué es importante mostrar amor desinteresado?
A73: 70 | B73: ¿Por qué se merece Dios toda nuestra confianza?
A74: 71 | B74: Ahora es el momento de estar despiertos
A75: 72 | B75: El amor identifica a la religión verdadera
A76: 73 | B76: Consigamos que nuestro corazón sea sabio
...

Sheet Nos visitan 2026
E2: DISCURSOS PUBLICOS | L2: Anotaciones adicionales
E3: Visitas a la congregación "El Castillo"
A5: Hospitalidad | B5: aseo | E5: Enero
A6: Grupo | C6: Discursante | E6: # | F6: Tema | H6: Canción | I6: Hora | J6: Fecha | L6: Verificar | N6: Numero de contacto | O6: ¿Asistio? | P6: ¿Presento otro bosquejo?
A7: 1 | B7: 6 | C7: Azahel Ramirez | E7: 32 | F7: Cómo enfrentarse a las inquietudes de la vida | H7: 3 | I7: 0.41666667 | J7: 46026 | K7: =IF(F7 <> "", F7, _xlfn.XLOOKUP(E7, 'Lista de bosquejos'!A4:A197, 'Lista de bosquejos'!B4:B197, "Discurso no encontrado")) -> Cómo enfrentarse a las inquietudes de la vida | L7: =IFERROR( _xlfn.LET( _xlpm.fila_encontrada, MATCH(F7, 'Lista de bosquejos'!B4:B237, 0), _xlpm.fecha_C, INDEX('Lista de bosquejos'!C4:C237, _xlpm.fila_encontrada), _xlpm.fecha_D, INDEX('Lista de bosquejos'!D4:D237, _xlpm.fila_encontrada), _xlpm.fecha_evaluar, MAX(_xlpm.fecha_C, _xlpm.fecha_D), _xlpm.diferencia, J7 - _xlpm.fecha_evaluar, IF(_xlpm.diferencia = 0, "Listo", IF(AND(_xlpm.diferencia > 1, _xlpm.diferencia < 365), "Reciente", "No reciente") ) ), "¡No encontrado!" ) -> Listo | M7: =IFERROR(MATCH(F7, 'Lista de bosquejos'!B4:B197, 0), "¿?") -> 32 | O7: Si
C8: Congregación El Castillo
A9: 2 | B9: 1 | C9: Luis Muñoz | E9: 189 | F9: ¿Faltará menos de lo que usted cree? | H9: 150 | I9: 0.41666667 | J9: 46033 | K9: =IF(F9 <> "", F9, _xlfn.XLOOKUP(E9, 'Lista de bosquejos'!A4:A197, 'Lista de bosquejos'!B4:B197, "Discurso no encontrado")) -> ¿Faltará menos de lo que usted cree? | L9: =IFERROR( _xlfn.LET( _xlpm.fila_encontrada, MATCH(F9, 'Lista de bosquejos'!B4:B237, 0), _xlpm.fecha_C, INDEX('Lista de bosquejos'!C4:C237, _xlpm.fila_encontrada), _xlpm.fecha_D, INDEX('Lista de bosquejos'!D4:D237, _xlpm.fila_encontrada), _xlpm.fecha_evaluar, MAX(_xlpm.fecha_C, _xlpm.fecha_D), _xlpm.diferencia, J9 - _xlpm.fecha_evaluar, IF(_xlpm.diferencia = 0, "Listo", IF(AND(_xlpm.diferencia > 1, _xlpm.diferencia < 365), "Reciente", "No reciente") ) ), "¡No encontrado!" ) -> Listo | M9: =IFERROR(MATCH(F9, 'Lista de bosquejos'!B4:B197, 0), "¿?") -> 181 | O9: Si
C10: Congregación El Castillo
B11: 2 | F11: Visita del superintendente de circuito | I11: 0.41666667 | J11: 46040 | K11: =IF(F11 <> "", F11, _xlfn.XLOOKUP(E11, 'Lista de bosquejos'!A4:A197, 'Lista de bosquejos'!B4:B197, "Discurso no encontrado")) -> Visita del superintendente de circuito | L11: =IFERROR( _xlfn.LET( _xlpm.fila_encontrada, MATCH(F11, 'Lista de bosquejos'!B4:B237, 0), _xlpm.fecha_C, INDEX('Lista de bosquejos'!C4:C237, _xlpm.fila_encontrada), _xlpm.fecha_D, INDEX('Lista de bosquejos'!D4:D237, _xlpm.fila_encontrada), _xlpm.fecha_evaluar, MAX(_xlpm.fecha_C, _xlpm.fecha_D), _xlpm.diferencia, J11 - _xlpm.fecha_evaluar, IF(_xlpm.diferencia = 0, "Listo", IF(AND(_xlpm.diferencia > 1, _xlpm.diferencia < 365), "Reciente", "No reciente") ) ), "¡No encontrado!" ) -> ¡No encontrado! | M11: =IFERROR(MATCH(F11, 'Lista de bosquejos'!B4:B197, 0), "¿?") -> ¿? | O11: Si
A13: 4 | B13: 3 | C13: Ramón Rojas | E13: 66 | F13: ¿Será usted un buen trabajador en la cosecha? | H13: 64 | I13: 0.41666667 | J13: 46047 | K13: =IF(F13 <> "", F13, _xlfn.XLOOKUP(E13, 'Lista de bosquejos'!A4:A197, 'Lista de bosquejos'!B4:B197, "Discurso no encontrado")) -> ¿Será usted un buen trabajador en la cosecha? | L13: =IFERROR( _xlfn.LET( _xlpm.fila_encontrada, MATCH(F13, 'Lista de bosquejos'!B4:B237, 0), _xlpm.fecha_C, INDEX('Lista de bosquejos'!C4:C237, _xlpm.fila_encontrada), _xlpm.fecha_D, INDEX('Lista de bosquejos'!D4:D237, _xlpm.fila_encontrada), _xlpm.fecha_evaluar, MAX(_xlpm.fecha_C, _xlpm.fecha_D), _xlpm.diferencia, J13 - _xlpm.fecha_evaluar, IF(_xlpm.diferencia = 0, "Listo", IF(AND(_xlpm.diferencia > 1, _xlpm.diferencia < 365), "Reciente", "No reciente") ) ), "¡No encontrado!" ) -> Listo | M13: =IFERROR(MATCH(F13, 'Lista de bosquejos'!B4:B197, 0), "¿?") -> 66 | O13: Si
C14: Congregación El Castillo
A17: Hospitalidad | B17: aseo | E17: Febrero
A18: Grupo | C18: Discursante | E18: # | F18: Tema | H18: Canción | I18: Hora | J18: Fecha | L18: Verificar | N18: Numero de contacto | O18: ¿Asistio? | P18: ¿Presento otro bosquejo?
A19: 5 | B19: 4 | C19: Abel Rojas | E19: 113 | F19: Joven, ¿cómo puedes ser feliz y tener éxito? | I19: 0.41666667 | J19: 46054 | K19: =IF(F19 <> "", F19, _xlfn.XLOOKUP(E19, 'Lista de bosquejos'!A4:A197, 'Lista de bosquejos'!B4:B197, "Discurso no encontrado")) -> Joven, ¿cómo puedes ser feliz y tener éxito? | L19: =IFERROR( _xlfn.LET( _xlpm.fila_encontrada, MATCH(F19, 'Lista de bosquejos'!B4:B237, 0), _xlpm.fecha_C, INDEX('Lista de bosquejos'!C4:C237, _xlpm.fila_encontrada), _xlpm.fecha_D, INDEX('Lista de bosquejos'!D4:D237, _xlpm.fila_encontrada), _xlpm.fecha_evaluar, MAX(_xlpm.fecha_C, _xlpm.fecha_D), _xlpm.diferencia, J19 - _xlpm.fecha_evaluar, IF(_xlpm.diferencia = 0, "Listo", IF(AND(_xlpm.diferencia > 1, _xlpm.diferencia < 365), "Reciente", "No reciente") ) ), "¡No encontrado!" ) -> Listo | M19: =IFERROR(MATCH(F19, 'Lista de bosquejos'!B4:B197, 0), "¿?") -> 113 | O19: Si
C20: Congregación El Castillo
A21: 3 | B21: 5 | C21: Juan Gilberto Diaz | E21: 99 | F21: Por qué se puede confiar en la Biblia | I21: 0.41666667 | J21: 46061 | K21: =IF(F21 <> "", F21, _xlfn.XLOOKUP(E21, 'Lista de bosquejos'!A4:A197, 'Lista de bosquejos'!B4:B197, "Discurso no encontrado")) -> Por qué se puede confiar en la Biblia | L21: =IFERROR( _xlfn.LET( _xlpm.fila_encontrada, MATCH(F21, 'Lista de bosquejos'!B4:B237, 0), _xlpm.fecha_C, INDEX('Lista de bosquejos'!C4:C237, _xlpm.fila_encontrada), _xlpm.fecha_D, INDEX('Lista de bosquejos'!D4:D237, _xlpm.fila_encontrada), _xlpm.fecha_evaluar, MAX(_xlpm.fecha_C, _xlpm.fecha_D), _xlpm.diferencia, J21 - _xlpm.fecha_evaluar, IF(_xlpm.diferencia = 0, "Listo", IF(AND(_xlpm.diferencia > 1, _xlpm.diferencia < 365), "Reciente", "No reciente") ) ), "¡No encontrado!" ) -> Listo | M21: =IFERROR(MATCH(F21, 'Lista de bosquejos'!B4:B197, 0), "¿?") -> 99
C22: Congregación El Castillo
B23: 6 | F23: Reunión especial visita a la sucursal de centroamerica | I23: 0.375 | J23: 46068 | K23: =IF(F23 <> "", F23, _xlfn.XLOOKUP(E23, 'Lista de bosquejos'!A4:A197, 'Lista de bosquejos'!B4:B197, "Discurso no encontrado")) -> Reunión especial visita a la sucursal de centroamerica | L23: =IFERROR( _xlfn.LET( _xlpm.fila_encontrada, MATCH(F23, 'Lista de bosquejos'!B4:B237, 0), _xlpm.fecha_C, INDEX('Lista de bosquejos'!C4:C237, _xlpm.fila_encontrada), _xlpm.fecha_D, INDEX('Lista de bosquejos'!D4:D237, _xlpm.fila_encontrada), _xlpm.fecha_evaluar, MAX(_xlpm.fecha_C, _xlpm.fecha_D), _xlpm.diferencia, J23 - _xlpm.fecha_evaluar, IF(_xlpm.diferencia = 0, "Listo", IF(AND(_xlpm.diferencia > 1, _xlpm.diferencia < 365), "Reciente", "No reciente") ) ), "¡No encontrado!" ) -> ¡No encontrado! | M23: =IFERROR(MATCH(F23, 'Lista de bosquejos'!B4:B197, 0), "¿?") -> ¿?
A25: 6 | B25: 1 | C25: Oscar Rojas Plascencia | E25: 169 | F25: ¿Por qué debemos guiarnos por la biblia? | H25: 98 | I25: 0.41666667 | J25: 46075 | K25: =IF(F25 <> "", F25, _xlfn.XLOOKUP(E25, 'Lista de bosquejos'!A4:A197, 'Lista de bosquejos'!B4:B197, "Discurso no encontrado")) -> ¿Por qué debemos guiarnos por la biblia? | L25: =IFERROR( _xlfn.LET( _xlpm.fila_encontrada, MATCH(F25, 'Lista de bosquejos'!B4:B237, 0), _xlpm.fecha_C, INDEX('Lista de bosquejos'!C4:C237, _xlpm.fila_encontrada), _xlpm.fecha_D, INDEX('Lista de bosquejos'!D4:D237, _xlpm.fila_encontrada), _xlpm.fecha_evaluar, MAX(_xlpm.fecha_C, _xlpm.fecha_D), _xlpm.diferencia, J25 - _xlpm.fecha_evaluar, IF(_xlpm.diferencia = 0, "Listo", IF(AND(_xlpm.diferencia > 1, _xlpm.diferencia < 365), "Reciente", "No reciente") ) ), "¡No encontrado!" ) -> Listo | M25: =IFERROR(MATCH(F25, 'Lista de bosquejos'!B4:B197, 0), "¿?") -> 169
C26: Congregación El Castillo
A31: Hospitalidad | B31: aseo | E31: Marzo
A32: Grupo | C32: Discursante | E32: # | F32: Tema | H32: Canción | I32: Hora | J32: Fecha | L32: Verificar | N32: Numero de contacto | O32: ¿Asistio? | P32: ¿Presento otro bosquejo?
A33: 1 | B33: 2 | C33: Ricardo Toledo | F33: ¿Tendrá usted la marca para sobrevivir? | I33: 0.41666667 | J33: 46082 | K33: =IF(F33 <> "", F33, _xlfn.XLOOKUP(E33, 'Lista de bosquejos'!A4:A197, 'Lista de bosquejos'!B4:B197, "Discurso no encontrado")) -> ¿Tendrá usted la marca para sobrevivir? | L33: =IFERROR( _xlfn.LET( _xlpm.fila_encontrada, MATCH(F33, 'Lista de bosquejos'!B4:B237, 0), _xlpm.fecha_C, INDEX('Lista de bosquejos'!C4:C237, _xlpm.fila_encontrada), _xlpm.fecha_D, INDEX('Lista de bosquejos'!D4:D237, _xlpm.fila_encontrada), _xlpm.fecha_evaluar, MAX(_xlpm.fecha_C, _xlpm.fecha_D), _xlpm.diferencia, J33 - _xlpm.fecha_evaluar, IF(_xlpm.diferencia = 0, "Listo", IF(AND(_xlpm.diferencia > 1, _xlpm.diferencia < 365), "Reciente", "No reciente") ) ), "¡No encontrado!" ) -> Listo | M33: =IFERROR(MATCH(F33, 'Lista de bosquejos'!B4:B197, 0), "¿?") -> 34
C34: Congregación El Castillo
A35: 2 | B35: 3 | C35: Christopher Cardenti | F35: ¿Anda usted por el camino que lleva a la vida eterna? | I35: 0.41666667 | J35: 46089 | K35: =IF(F35 <> "", F35, _xlfn.XLOOKUP(E35, 'Lista de bosquejos'!A4:A197, 'Lista de bosquejos'!B4:B197, "Discurso no encontrado")) -> ¿Anda usted por el camino que lleva a la vida eterna? | L35: =IFERROR( _xlfn.LET( _xlpm.fila_encontrada, MATCH(F35, 'Lista de bosquejos'!B4:B237, 0), _xlpm.fecha_C, INDEX('Lista de bosquejos'!C4:C237, _xlpm.fila_encontrada), _xlpm.fecha_D, INDEX('Lista de bosquejos'!D4:D237, _xlpm.fila_encontrada), _xlpm.fecha_evaluar, MAX(_xlpm.fecha_C, _xlpm.fecha_D), _xlpm.diferencia, J35 - _xlpm.fecha_evaluar, IF(_xlpm.diferencia = 0, "Listo", IF(AND(_xlpm.diferencia > 1, _xlpm.diferencia < 365), "Reciente", "No reciente") ) ), "¡No encontrado!" ) -> Listo | M35: =IFERROR(MATCH(F35, 'Lista de bosquejos'!B4:B197, 0), "¿?") -> 192
C36: Congregación El Castillo
A37: 5 | B37: 4 | C37: Cruz Colin | F37: Estemos muy pendientes del “impresionante día de Jehová” | I37: 0.41666667 | J37: 46096 | K37: {=IF(F37 <> "", F37, _xlfn.XLOOKUP(E, 'Lista de bosquejos'!A4:A197, 'Lista de bosquejos'!B4:B197, "Discurso no encontrado"))} -> Estemos muy pendientes del “impresionante día de Jehová” | L37: =IFERROR( _xlfn.LET( _xlpm.fila_encontrada, MATCH(F37, 'Lista de bosquejos'!B4:B237, 0), _xlpm.fecha_C, INDEX('Lista de bosquejos'!C4:C237, _xlpm.fila_encontrada), _xlpm.fecha_D, INDEX('Lista de bosquejos'!D4:D237, _xlpm.fila_encontrada), _xlpm.fecha_evaluar, MAX(_xlpm.fecha_C, _xlpm.fecha_D), _xlpm.diferencia, J37 - _xlpm.fecha_evaluar, IF(_xlpm.diferencia = 0, "Listo", IF(AND(_xlpm.diferencia > 1, _xlpm.diferencia < 365), "Reciente", "No reciente") ) ), "¡No encontrado!" ) -> Listo | M37: =IFERROR(MATCH(F37, 'Lista de bosquejos'!B4:B197, 0), "¿?") -> 153
C38: Congregación La Sirena
A39: 4 | B39: 5 | C39: Isaias Saenz | F39: Mire al futuro sin miedo | H39: 153 | I39: 0.66666667 | J39: 46102 | K39: =IF(F39<> "", F39, _xlfn.XLOOKUP(E39, 'Lista de bosquejos'!A4:A197, 'Lista de bosquejos'!B4:B197, "Discurso no encontrado")) -> Mire al futuro sin miedo | L39: =IFERROR( _xlfn.LET( _xlpm.fila_encontrada, MATCH(F39, 'Lista de bosquejos'!B4:B237, 0), _xlpm.fecha_C, INDEX('Lista de bosquejos'!C4:C237, _xlpm.fila_encontrada), _xlpm.fecha_D, INDEX('Lista de bosquejos'!D4:D237, _xlpm.fila_encontrada), _xlpm.fecha_evaluar, MAX(_xlpm.fecha_C, _xlpm.fecha_D), _xlpm.diferencia, J39 - _xlpm.fecha_evaluar, IF(_xlpm.diferencia = 0, "Listo", IF(AND(_xlpm.diferencia > 1, _xlpm.diferencia < 365), "Reciente", "No reciente") ) ), "¡No encontrado!" ) -> Listo | M39: =IFERROR(MATCH(F39, 'Lista de bosquejos'!B4:B197, 0), "¿?") -> 108
C40: Congregación Redonda
A41: 3 | B41: 6 | C41: Hector Perez | F41: Discurso especial 2026 ¿Quién salvara el planeta? | I41: 0.41666667 | J41: 46110 | K41: =IF(F41 <> "", F41, _xlfn.XLOOKUP(E41, 'Lista de bosquejos'!A4:A197, 'Lista de bosquejos'!B4:B197, "Discurso no encontrado")) -> Discurso especial 2026 ¿Quién salvara el planeta? | L41: =IFERROR( _xlfn.LET( _xlpm.fila_encontrada, MATCH(F41, 'Lista de bosquejos'!B4:B237, 0), _xlpm.fecha_C, INDEX('Lista de bosquejos'!C4:C237, _xlpm.fila_encontrada), _xlpm.fecha_D, INDEX('Lista de bosquejos'!D4:D237, _xlpm.fila_encontrada), _xlpm.fecha_evaluar, MAX(_xlpm.fecha_C, _xlpm.fecha_D), _xlpm.diferencia, J41 - _xlpm.fecha_evaluar, IF(_xlpm.diferencia = 0, "Listo", IF(AND(_xlpm.diferencia > 1, _xlpm.diferencia < 365), "Reciente", "No reciente") ) ), "¡No encontrado!" ) -> ¡No encontrado! | M41: =IFERROR(MATCH(F41, 'Lista de bosquejos'!B4:B197, 0), "¿?") -> ¿?
C42: Congregación El Verde
A45: Hospitalidad | B45: aseo | E45: Abril
A46: Grupo | C46: Discursante | E46: # | F46: Tema | H46: Canción | I46: Hora | J46: Fecha | L46: Verificar | N46: Numero de contacto | O46: ¿Asistio? | P46: ¿Presento otro bosquejo?
A47: 6 | C47: Isvi Cobos | E47: 28 | F47: Muestre respeto y amor en su matrimonio | I47: 0.41666667 | J47: 46117 | K47: =IF(F47 <> "", F47, _xlfn.XLOOKUP(E49, 'Lista de bosquejos'!A4:A197, 'Lista de bosquejos'!B4:B197, "Discurso no encontrado")) -> Muestre respeto y amor en su matrimonio | L47: =IFERROR(IF(MATCH(F47, 'Lista de bosquejos'!B4:B197, 0), IF(AND(J47-INDEX('Lista de bosquejos'!D4:D197, MATCH(F47, 'Lista de bosquejos'!B4:B197, 0))>1, J47-INDEX('Lista de bosquejos'!D4:D197, MATCH(F47, 'Lista de bosquejos'!B4:B197, 0))<365), "Reciente", IF(J47=INDEX('Lista de bosquejos'!D4:D197, MATCH(F47, 'Lista de bosquejos'!B4:B197, 0)), "Listo", "No reciente")), "No encontrado"), "¡No encontrado!") -> No reciente | M47: =IFERROR(MATCH(F47, 'Lista de bosquejos'!B4:B197, 0), "¿?") -> 28
B48: 1 | C48: Congregación Campestre
F49: Asamblea de circuito | I49: 0.41666667 | J49: 46124 | K49: =IF(F49 <> "", F49, _xlfn.XLOOKUP(E49, 'Lista de bosquejos'!A4:A197, 'Lista de bosquejos'!B4:B197, "Discurso no encontrado")) -> Asamblea de circuito | L49: =IFERROR(IF(MATCH(F49, 'Lista de bosquejos'!B4:B197, 0), IF(AND(J49-INDEX('Lista de bosquejos'!D4:D197, MATCH(F49, 'Lista de bosquejos'!B4:B197, 0))>1, J49-INDEX('Lista de bosquejos'!D4:D197, MATCH(F49, 'Lista de bosquejos'!B4:B197, 0))<365), "Reciente", IF(J49=INDEX('Lista de bosquejos'!D4:D197, MATCH(F49, 'Lista de bosquejos'!B4:B197, 0)), "Listo", "No reciente")), "No encontrado"), "¡No encontrado!") -> ¡No encontrado! | M49: =IFERROR(MATCH(F49, 'Lista de bosquejos'!B4:B197, 0), "¿?") -> ¿?
A51: 1 | C51: Noe Zatarain Perez | E51: 157 | F51: Cómo adornan los cristianos la enseñanza divina | I51: 0.41666667 | J51: 46131 | K51: =IF(F51 <> "", F51, _xlfn.XLOOKUP(E51, 'Lista de bosquejos'!A4:A197, 'Lista de bosquejos'!B4:B197, "Discurso no encontrado")) -> Cómo adornan los cristianos la enseñanza divina | L51: =IFERROR(IF(MATCH(F51, 'Lista de bosquejos'!B4:B197, 0), IF(AND(J51-INDEX('Lista de bosquejos'!D4:D197, MATCH(F51, 'Lista de bosquejos'!B4:B197, 0))>1, J51-INDEX('Lista de bosquejos'!D4:D197, MATCH(F51, 'Lista de bosquejos'!B4:B197, 0))<365), "Reciente", IF(J51=INDEX('Lista de bosquejos'!D4:D197, MATCH(F51, 'Lista de bosquejos'!B4:B197, 0)), "Listo", "No reciente")), "No encontrado"), "¡No encontrado!") -> No reciente | M51: =IFERROR(MATCH(F51, 'Lista de bosquejos'!B4:B197, 0), "¿?") -> 157
B52: 2 | C52: Congregación Campestre
A53: 2 | C53: Omar Meza | E53: 18 | F53: Haga de Jehová su “fortaleza” | I53: 0.41666667 | J53: 46138 | K53: =IF(F53 <> "", F53, _xlfn.XLOOKUP(E53, 'Lista de bosquejos'!A4:A197, 'Lista de bosquejos'!B4:B197, "Discurso no encontrado")) -> Haga de Jehová su “fortaleza” | L53: =IFERROR(IF(MATCH(F53, 'Lista de bosquejos'!B4:B197, 0), IF(AND(J53-INDEX('Lista de bosquejos'!D4:D197, MATCH(F53, 'Lista de bosquejos'!B4:B197, 0))>1, J53-INDEX('Lista de bosquejos'!D4:D197, MATCH(F53, 'Lista de bosquejos'!B4:B197, 0))<365), "Reciente", IF(J53=INDEX('Lista de bosquejos'!D4:D197, MATCH(F53, 'Lista de bosquejos'!B4:B197, 0)), "Listo", "No reciente")), "No encontrado"), "¡No encontrado!") -> No reciente | M53: =IFERROR(MATCH(F53, 'Lista de bosquejos'!B4:B197, 0), "¿?") -> 18
...

Sheet Visitamos 2026
D2: ROL DE DISCURSOS | J2: Anotaciones adicionales
D3: Congregaciones que nos tocá visitar
D5: Enero
B6: Congregación: | D6: Mar de Cortés | F6: Dia y hora: | G6: Domingo 2:00 pm
B7: Ubicación: | D7: Calle Francisco Villa #605 entre deportista y Lázaro Cárdenas, Colonia Salvador Allende
B8: ='Nos visitan 2026'!C6 -> Discursante | D8: Tema | F8: Canción | G8: Hora | H8: Fecha | J8: Numero de contacto | K8: ¿Asistio? | L8: ¿Presento otro bosquejo?
D9: Asamblea de circuito | H9: 45298
B11: Ricardo Toledo Saenz | D11: Alejemos la mirada de lo que es inútil | G11: 0.58333333 | H11: 45305
B13: Carlos R. Sánchez Toledo | D13: ¿Por qué andar en el camino de Dios? | G13: 0.58333333 | H13: 45312
B15: Oscar A. Rojas Barrios | D15: ¿Como tomará usted sus decisiones? | G15: 0.58333333 | H15: 45319
D19: Febrero
B20: Congregación: | D20: Estrella del Mar | F20: Dia y hora: | G20: Domingo 9:30 am
B21: Ubicación: | D21: Barron, sinaloa
B22: Discursante | D22: Tema | F22: Canción | G22: Hora | H22: Fecha | J22: Numero de contacto | K22: ¿Asistio? | L22: ¿Presento otro bosquejo?
H23: 45326
H25: 45333
B27: Gerson Daniel Saenz Lizarraga | D27: ¿Qué pruebas demuestran la autenticidad de la Biblia? | G27: 0.375 | H27: 45340
B29: Ramón Rojas Barrios | D29: ¿Sobreviviremos a los ultimos días? | G29: 0.375 | H29: 45347
D33: Marzo
B34: Congregación: | D34: Estrella del Mar | F34: Dia y hora: | G34: Sabado 4:00 pm
B35: Ubicación: | D35: Barron, Sinaloa
B36: Discursante | D36: Tema | F36: Canción | G36: Hora | H36: Fecha | J36: Numero de contacto | K36: ¿Asistio? | L36: ¿Presento otro bosquejo?
B37: Saul Salas Quiñones | D37: ¿Como obtener consuelo en toda tribulación? | G37: 0.66666667 | H37: 45352
B39: Azahel Ramirez | D39: Consigamos que nuestro corazón sea sabio | F39: 36 | G39: 0.66666667 | H39: 45359
B41: Daniel Saenz Lizarraga | D41: ¿Qué pruebas demuestran la autenticidad de la Biblia? | F41: 98 | G41: 0.66666667 | H41: 45366
D43: No hay salidas | G43: 0.66666667 | H43: 45373
D45: Asamblea de circuito | G45: 0.66666667 | H45: 45380
D49: Abril
B50: Congregación: | D50: Pino Suarez | F50: Dia y hora: | G50: Sabado 7:00 pm
B51: Ubicación: | D51: Escolar 28, Urías, 82099 Mazatlán, Sin.
B52: Discursante | D52: Tema | F52: Canción | G52: Hora | H52: Fecha | J52: Numero de contacto | K52: ¿Asistio? | L52: ¿Presento otro bosquejo?
D53: Asamblea de circuito | G53: 0.79166667 | H53: 44658
B55: Carlos Rafael Sanchez Toledo | G55: 0.79166667 | H55: 44665
B57: Oscar Abel Rojas Barrios | G57: 0.79166667 | H57: 44672
B59: Gerson Daniel Saenz Lizarraga | G59: 0.79166667 | H59: 44679
B61: Marco Antonio Zatarain Barron | G61: 0.79166667 | H61: 44686
D65: Mayo
B66: Congregación: | D66: Olimpica | F66: Dia y hora: | G66: Domingo 4:00 PM
B67: Ubicación: | D67: Calle Pedro Infante #3705, Colonia Olímpica, 82150 Mazatlán, Sin.
B68: Discursante | D68: Tema | F68: Canción | G68: Hora | H68: Fecha | J68: Numero de contacto | K68: ¿Asistio? | L68: ¿Presento otro bosquejo?
...

Sheet Formato
B2: Oradores congregación "El Castillo"
B3: Reunión: Domingo 10:00 am
B4: Coordinador de discursos: Marco A. Zatarain | F4: Número celular: 6691907833
B6: Nombre | C6: Luis Muñoz | G6: Anciano
B7: Contacto | C7: +52 669 593 2761 | G7: Cong. El Castillo
B8: No. | C8: Tema | H8: Canción
B9: 52 | C9: ¿Quién es su dios? | H9: 2
C10: ¿Faltará menos de lo que usted cree?
B12: Nombre | C12: Marco Antonio Zatarain Barrón | G12: Anciano
B13: Contacto | C13: +52 6691907833 | G13: Cong. El Castillo
B14: No. | C14: Tema | H14: Canción
B15: 4 | C15: El mundo que nos rodea prueba que Dios existe | H15: 5
B16: 96 | C16: ¿Cuál es el futuro de la religión? | H16: 32
B17: 71 | C17: Ahora es el momento de estar despiertos | H17: 126
B19: Nombre | C19: Saúl Salas Quiñones | G19: Anciano
B20: Contacto | C20: +52 6691659845 | G20: Cong. El Castillo
B21: No. | C21: Tema | H21: Canción
B22: 105 | C22: ¿Como obtener consuelo en toda tribulación?
B23: 45 | C23: "Siga el camino a la vida"
B26: Nombre | C26: Azahel Ramirez | G26: Anciano
B27: Contacto | C27: +52 669 273 6232 | G27: Cong. El Castillo
B28: No. | C28: Tema | H28: Canción
B29: 41 | C29: "Estense quietos y vean cómo los salva Jehová" | H29: 122
B30: 57 | C30: Aguantemos la persecución | H30: 128
B31: 67 | C31: Medite en la Palabra de Jehová y en su creación | H31: 45
B32: 73 | C32: Consigamos que nuestro corazón sea sabio | H32: 36
B35: Nombre | C35: Gerson Daniel Saenz Lizarraga | G35: Anciano
B36: Contacto | C36: +52 6691661333 | G36: Cong. El Castillo
B37: No. | C37: Tema | H37: Canción
B38: 175 | C38: ¿Qué pruebas demuestran la autenticidad de la Biblia? | H38: 98
B39: 187 | C39: ¿Cómo es posible que un Dios de amor permita la maldad? | H39: 115
B43: Nombre | C43: Ramón Rojas Barrios | G43: Anciano
B44: Contacto | C44: +52 6692518642 | G44: Cong. El Castillo
B45: No. | C45: Tema | H45: Canción
B46: 2 | C46: ¿Sobreviviremos a los ultimos días?
B47: 189 | C47: Andar con Dios nos beneficia ahora y para siempre | H47: 31
B51: Nombre | C51: Fidel Arturo Cardenas F. | G51: Siervo Ministerial
B52: Contacto | C52: +52 669 134 6338 | G52: Cong. El Castillo
B53: No. | C53: Tema | H53: Canción
B54: 77 | C54: “Sean siempre hospitalarios”
...

Sheet Nuestros oradores
B1: Oradores congregación "El Castillo"
B2: Reunión: Sabado 6:00 PM
B3: Coordinador de discursos: Marco A. Zatarain | F3: Número celular: 6691907833
B5: Nombre | C5: Ricardo Toledo Saenz | G5: Anciano
B6: Contacto | C6: +52 6692680928 | G6: Cong. El Castillo
B7: No. | C7: Tema | H7: Canción
B8: 6 | C8: ¿Qué aprendemos del Diluvio universal?
B9: 18 | C9: Haga de Jehová su "fortaleza" | H9: 8
B10: 183 | C10: Alejemos la mirada de lo que es inútil | H10: 126
B13: Nombre | C13: Marco Antonio Zatarain Barrón | G13: Anciano
B14: Contacto | C14: +52 6691907833 | G14: Cong. El Castillo
B15: No. | C15: Tema | H15: Canción
B16: 4 | C16: El mundo que nos rodea prueba que Dios existe | H16: 5
B17: 96 | C17: ¿Cuál es el futuro de la religión? | H17: 32
B18: 71 | C18: Ahora es el momento de estar despiertos | H18: 126
B20: Nombre | C20: Saúl Salas Quiñones | G20: Anciano
B21: Contacto | C21: +52 6691659845 | G21: Cong. El Castillo
B22: No. | C22: Tema | H22: Canción
B23: 105 | C23: ¿Como obtener consuelo en toda tribulación?
B24: 45 | C24: "Siga el camino a la vida"
B27: Nombre | C27: Azahel Ramirez | G27: Anciano
B28: Contacto | C28: +52 669 273 6232 | G28: Cong. El Castillo
B29: No. | C29: Tema | H29: Canción
B30: 41 | C30: "Estense quietos y vean cómo los salva Jehová" | H30: 122
B31: 57 | C31: Aguantemos la persecución | H31: 128
B32: 67 | C32: Medite en la Palabra de Jehová y en su creación | H32: 45
B33: 73 | C33: Consigamos que nuestro corazón sea sabio | H33: 36
B35: Nombre | C35: Oscar Abel Rojas Barrios | G35: Anciano
B36: Contacto | C36: +52 6691973020 | G36: Cong. El Castillo
B37: No. | C37: Tema | H37: Canción
B38: 50 | C38: ¿Como tomará usted sus decisiones?
B39: 177 | C39: ¿A quien podemos acudir en tiempos de angustia?
B40: 5 | C40: Ayuda práctica para las familias
B41: 126 | C41: Porque deben ser diferentes los cristianos
B42: 190 | C42: Una familia unida y feliz para siempre | H42: 136
B44: Nombre | C44: Gerson Daniel Saenz Lizarraga | G44: Anciano
B45: Contacto | C45: +52 6691661333 | G45: Cong. El Castillo
B46: No. | C46: Tema | H46: Canción
B47: 175 | C47: ¿Qué pruebas demuestran la autenticidad de la Biblia? | H47: 98
B48: 187 | C48: ¿Cómo es posible que un Dios de amor permita la maldad? | H48: 115
...

Sheet Base de datos
B2: Registro de roles | J2: Orden para salir
J3: Ricardo T. | L3: A
B4: 2023 | J4: Marco Z | L4: A
B5: Meses | D5: Congregación | J5: Saul Salas | L5: A
B6: Enero | D6: Local | J6: Azahel Ramirez | L6: A
B7: Febrero | D7: Local | J7: Oscar Rojas | L7: A
B8: Marzo | D8: Lomas de Juarez | J8: Daniel Saenz | L8: A
B9: Abril | D9: Carranza | J9: Ramon Rojas | L9: A
B10: Mayo | D10: La Sirena | J10: Fidel Cardenaz | L10: SM
B11: Junio | D11: Santa Fe | J11: Luis Muñoz | L11: A
B12: Julio | D12: El Roble | J12: Carlos Sanchez | L12: SM
B13: Agosto | D13: El Roble
B14: Septiembre | D14: Tulipan
B15: Octubre | D15: Pradera Dorada
B16: Noviembre | D16: Pradera Dorada | J16: abel
B17: Diciembre | D17: Costa dorada | J17: juan
J18: chris
B19: 2024 | J19: oscar
B20: Meses | D20: Congregación | J20: fidel
B21: Enero | D21: Mar de Cortez | J21: luis
B22: Febrero | D22: Naval
B23: Marzo | D23: Campestre
B24: Abril | D24: Pino Suarez
B25: Mayo | D25: Rol local
B26: Junio | D26: Rol local
B27: Julio | D27: Invitaciones
B28: Agosto | D28: Insurgentes
B29: Septiembre | D29: Estadio
B30: Octubre
B31: Noviembre
B32: Diciembre
B34: 2025
B35: Meses | D35: Congregación
B36: Enero | D36: Francisco Villa
B37: Febrero | D37: Santa Fe | F37: m
B38: Marzo | D38: Barron
B39: Abril | D39: Redonda | F39: m
B40: Mayo | D40: Olimpica
B41: Junio | D41: Villas del sol | F41: m
B42: Julio | D42: Tronconal
...

Sheet Canciones sugeridas
A1: N° | B1: Titulo | C1: Tema | D1: Canción | E1: Opcional
A2: 1 | B2: ¿Conoce bien a Dios? | C2: FE/ESPIRITUALIDAD | D2: 2, 4
A3: 2 | B3: ¿Sobreviviremos a los últimos días? | C3: ULTIMOS DIAS/JUICIO DE DIOS | D3: 139, 144
A4: 3 | B4: Avancemos con la organización unida de Jehová | C4: RELIGION/ADORACION | D4: 101
A5: 4 | B5: El mundo que nos rodea prueba que Dios existe | C5: BIBLIA/DIOS | D5: 6, 11
A6: 5 | B6: Ayuda práctica para las familias | C6: FAMILIA/JOVENES | D6: 131, 132
A7: 6 | B7: ¿Qué aprendemos del diluvio de los días de Noé? | C7: ULTIMOS DIAS/JUICIO DE DIOS | D7: 150
A8: 7 | B8: Imitemos al "padre de tiernas misericordias" | C8: NORMAS Y CUALIDADES CRISTIANAS | D8: 125
A9: 8 | B9: Vivamos para hacer la voluntad de Dios, no la nuestra | C9: RELIGION/ADORACION | D9: 21
A10: 9 | B10: Escuchemos y pongamos en práctica la Palabra de Dios | C10: FE/ESPIRITUALIDAD | D10: 127
A11: 10 | B11: Seamos honrados en todo | C11: NORMAS Y CUALIDADES CRISTIANAS | D11: 121
A12: 11 | B12: Imitemos a Jesús, y no seamos parte del mundo | C12: MUNDO, NO SER PARTE DEL | D12: 13
A13: 12 | B13: A Dios le importa como vemos la autoridad | C13: NORMAS Y CUALIDADES CRISTIANAS | D13: 123
A14: 13 | B14: Cómo ve Dios el sexo y el matrimonio | C14: FAMILIA/JOVENES | D14: 131
A15: 14 | B15: Un pueblo limpio da gloria a Jehová | C15: NORMAS Y CUALIDADES CRISTIANAS | D15: 29, 39
A16: 15 | B16: "Hagamos el bien a todos" | C16: NORMAS Y CUALIDADES CRISTIANAS | D16: 106
A17: 16 | B17: Fortalezcamos nuestra amistad con Dios | C17: FE/ESPIRITUALIDAD | D17: 31
A18: 17 | B18: Demos gloria a Dios con todo lo que tenemos | C18: EVANGELIZACION/MINISTERIO | D18: 35
A19: 18 | B19: Haga de Jehová su "fortaleza" | C19: FE/ESPIRITUALIDAD | D19: 148
A20: 19 | B20: Cómo puede usted conocer su futuro | C20: REINO/PARAISO | D20: 142
A21: 20 | B21: ¿Ha llegado el tiempo para que Dios gobierne el mundo? | C21: ULTIMOS DIAS/JUICIO DE DIOS | D21: 9
A22: 21 | B22: Valoremos nuestro lugar en el Reino de Dios | C22: REINO/PARAISO | D22: 21
A23: 22 | B23: ¿Aprovecha usted todas las ayudas espirituales que Jehová nos da? | C23: FE/ESPIRITUALIDAD | D23: 20
A24: 23 | B24: La vida tiene propósito | C24: REINO/PARAISO | D24: 141
A25: 24 | B25: ¿Ha encontrado usted "una perla muy valiosa"? | C25: REINO/PARAISO | D25: 23
A26: 25 | B26: Luchemos contra el espíritu del mundo | C26: MUNDO, NO SER PARTE DEL | D26: 128
A27: 26 | B27: (No está disponible) | C27: BIBLIA/DIOS
A28: 27 | B28: Cómo iniciar bien un matrimonio | C28: FAMILIA/JOVENES | D28: 131, 132
A29: 28 | B29: Muestre amor y respeto en su matrimonio | C29: FAMILIA/JOVENES | D29: 131, 132
A30: 29 | B30: Las responsabilidades y las recompensas que tienen los padres | C30: FAMILIA/JOVENES | D30: 134
A31: 30 | B31: Cómo mejorar la comunicación en la familia | C31: FAMILIA/JOVENES | D31: 47
A32: 31 | B32: ¿Estamos al tanto de nuestras necesidades espirituales? | C32: FE/ESPIRITUALIDAD | D32: 57, 58
A33: 32 | B33: Cómo enfrentarse a las inquietudes de la vida | C33: PRUEBAS/PROBLEMAS | D33: 38
A34: 33 | B34: ¿Habrá algún día justicia para todos? | C34: MUNDO, NO SER PARTE DEL | D34: 34, 36
A35: 34 | B35: ¿Está usted marcado para sobrevivir? | C35: ULTIMOS DIAS/JUICIO DE DIOS | D35: 139
A36: 35 | B36: ¿Se puede vivir para siempre? ¿Lo logrará usted? | C36: REINO/PARAISO | D36: 140, 141
A37: 36 | B37: ¿Es esta vida todo lo que podemos esperar? | C37: RELIGION/ADORACION | D37: 145, 146
A38: 37 | B38: ¿Por qué andar en el camino de Dios? | C38: REINO/PARAISO | D38: 24
A39: 38 | B39: ¿Cómo puede usted sobrevivir al fin del mundo? | C39: ULTIMOS DIAS/JUICIO DE DIOS | D39: 34, 122
A40: 39 | B40: !Seguros de la victoria divina! | C40: BIBLIA/DIOS | D40: 149
...
